Workbook

Sheet Generales
A1: 2025 | B1: 5
B2: Período
B3: Fecha de inicio | C3: Fecha final | D3: Días de revisión | E3: Años de revisión
B4: 45909 | C4: 46010 | D4: =_xlfn.DAYS(C4,B4) -> 101 | E4: =D4/365 -> 0.27671233

Sheet Liquidación Laboral
A1: Salario Mensual Base | B1: 1423500 | C1: Año | D1: 2025
A2: Salario Quincenal | B2: =B1/2 -> 711750
A3: Auxilio de transporte | E3: Historico salarios mínimos
A4: Días trabajados en el Semestre | B4: 180 | F4: 2019 | G4: 2020 | H4: 2021 | I4: 2022 | J4: 2023 | K4: 2024 | L4: 2025 | M4: 2026
A5: Días trabajados en el Año | B5: 360 | E5: Salario Mensual | F5: 828211 | G5: 877802 | H5: 908526 | I5: 1000000 | J5: 1160000 | K5: 1300000 | L5: 1423500
A6: Salud Empleado | B6: =B1*0.04 -> 56940 | E6: Auxilio de transporte | F6: 97032 | G6: 102853 | H6: 106454 | I6: 117172 | J6: 140606 | K6: 162000 | L6: 200000
A7: Salud Empleador | B7: =IF(F19<2,B1*0.085,IF(B1/HLOOKUP(D1,F4:M6,2,FALSE)>10,B1*0.085,0)) -> 0 | F7: =F5*2 -> 1656422 | G7: =G5*2 -> 1755604 | H7: =H5*2 -> 1817052 | I7: =I5*2 -> 2000000 | J7: =J5*2 -> 2320000 | K7: =K5*2 -> 2600000 | L7: =L5*2 -> 2847000
A8: Pensión Empleado | B8: =B1*0.04 -> 56940 | E8: Nivel de Riesgo | F8: Porcentaje | G8: Riesgo iv | H8: Riesgo del Empleado
A9: Pensión Empleador | B9: =B1*0.12 -> 170820 | E9: Riesgo I | F9: 0.00522
A10: ARL | B10: =B1*(VLOOKUP(G8,E9:F13,2,FALSE)) -> 61922.25 | E10: Riesgo II | F10: 0.01044
A11: Prima | B11: =((B1+B3)*B4/360) -> 711750 | E11: Riesgo III | F11: 0.02436
A12: Cesantías | B12: =((B1+B3)*B5/360) -> 1423500 | E12: Riesgo IV | F12: 0.0435 | I12: ARTÍCULO 114-1 Estatuto Tributario. Así mismo las personas naturales empleadoras estarán exoneradas de la obligación de pago de los aportes parafiscales al SENA, al ICBF y al Sistema de Seguridad Social en Salud por los empleados que devenguen menos de diez (10) salarios mínimos legales mensuales vigentes. Lo anterior no aplicará para personas naturales que empleen menos de dos trabajadores, los cuales seguirán obligados a efectuar los aportes de que trata este inciso.
A13: Intereses a las Cesantías | B13: =(B12*B5*0.12)/360 -> 170820 | E13: Riesgo V | F13: 0.0696
A14: Cesantías + intereses | B14: =B12+B13 -> 1594320
A15: Vacaciones | B15: =(B1*B5)/720 -> 711750
A16: Fondo de solidaridad pensional | B16: =IF(B1/HLOOKUP(D1,F4:M7,2,FALSE)>4,B1*1%,0) -> 0
A17: Cajas de compensación familiar | B17: =IF(F19<2,B1*0.04,IF(B1/HLOOKUP(D1,F4:M7,2,FALSE)>10,B1*0.04,0)) -> 0 | E17: Total Días | F17: Día inicial | G17: Dia final
A18: I.C.B.F. (3%). | B18: =IF(F19<2,B1*0.03,IF(B1/HLOOKUP(D1,F4:M7,2,FALSE)>10,B1*0.03,0)) -> 0 | E18: =DAYS360(F18,G18) -> 150 | F18: 44774 | G18: 44926
A19: Sena | B19: =IF(F19<2,B1*0.02,IF(B1/HLOOKUP(D1,F4:M7,2,FALSE)>10,B1*0.02,0)) -> 0 | E19: Total empleados | F19: 2

Sheet Calendario Tributario
B1: Fechas de Retención en la Fuente | N1: Fechas IVA Bimestral | W1: Fechas IVA Cuatrimestral
A2: Número mes | B2: MES | C2: Último dig | D2: DATO UN | E2: 2018 | F2: 2019 | G2: 2020 | H2: 2021 | I2: 2022 | J2: 2023 | K2: 2024 | L2: 2025 | N2: DATO UN | O2: Último Dig | P2: 2019 | Q2: 2020 | R2: 2021 | S2: 2022 | T2: 2023 | U2: 2024 | W2: DATO UN | X2: Último Dig | Y2: 2019 | Z2: 2020 | AA2: 2021 | AB2: 2022 | AC2: 2023 | AD2: 2024 | AF2: Últ Dígito
A3: 1 | B3: ENERO | C3: 0 | D3: =CONCATENATE(B3,C3) -> ENERO0 | E3: 43139 | F3: 43504 | G3: 43872 | H3: 44249 | I3: 44613 | J3: 44977 | K3: 45344 | L3: 45712 | N3: Enero - Febrero | O3: 0 | W3: Enero - Abril | X3: 0 | AF3: 0
A4: 2 | B4: FEBRERO | C4: 0 | D4: =CONCATENATE(B4,C4) -> FEBRERO0 | E4: 43167 | F4: 43532 | G4: 43900 | H4: 44278 | I4: 44642 | J4: 45006 | K4: 45373 | L4: 45741 | N4: Marzo - Abril | O4: 0 | W4: Mayo - Agosto | X4: 0 | AF4: 1
A5: 3 | B5: MARZO | C5: 0 | D5: =CONCATENATE(B5,C5) -> MARZO0 | E5: 43200 | F5: 43564 | G5: 43935 | H5: 44309 | I5: 44673 | J5: 45037 | K5: 45404 | L5: 45771 | N5: Mayo - Junio | O5: 0 | W5: Septiembre - Diciembre | X5: 0 | AF5: 2
A6: 4 | B6: ABRIL | C6: 0 | D6: =CONCATENATE(B6,C6) -> ABRIL0 | E6: 43229 | F6: 43594 | G6: 43963 | H6: 44340 | I6: 44704 | J6: 45069 | K6: 45436 | L6: 45800 | N6: Julio - Agosto | O6: 0 | W6: Enero - Abril | X6: 1 | AF6: 3
A7: 5 | B7: MAYO | C7: 0 | D7: =CONCATENATE(B7,C7) -> MAYO0 | E7: 43264 | F7: 43627 | G7: 43991 | H7: 44370 | I7: 44733 | J7: 45099 | K7: 45469 | L7: 45833 | N7: Septiembre - Octubre | O7: 0 | W7: Mayo - Agosto | X7: 1 | AF7: 4
A8: 6 | B8: JUNIO | C8: 0 | D8: =CONCATENATE(B8,C8) -> JUNIO0 | E8: 43291 | F8: 43655 | G8: 44019 | H8: 44399 | I8: 44764 | J8: 45128 | K8: 45496 | L8: 45860 | N8: Noviembre - Diciembre | O8: 0 | W8: Septiembre - Diciembre | X8: 1 | AF8: 5
A9: 7 | B9: JULIO | C9: 0 | D9: =CONCATENATE(B9,C9) -> JULIO0 | E9: 43321 | F9: 43686 | G9: 44054 | H9: 44432 | I9: 44796 | J9: 45161 | K9: 45530 | L9: 45895 | N9: Enero - Febrero | O9: 1 | W9: Enero - Abril | X9: 2 | AF9: 6
A10: 8 | B10: AGOSTO | C10: 0 | D10: =CONCATENATE(B10,C10) -> AGOSTO0 | E10: 43354 | F10: 43718 | G10: 44082 | H10: 44460 | I10: 44824 | J10: 45189 | K10: 45558 | L10: 45922 | N10: Marzo - Abril | O10: 1 | W10: Mayo - Agosto | X10: 2 | AF10: 7
A11: 9 | B11: SEPTIEMBRE | C11: 0 | D11: =CONCATENATE(B11,C11) -> SEPTIEMBRE0 | E11: 43382 | F11: 43746 | G11: 44110 | H11: 44490 | I11: 44855 | J11: 45223 | K11: 45588 | L11: 45953 | N11: Mayo - Junio | O11: 1 | W11: Septiembre - Diciembre | X11: 2 | AF11: 8
A12: 10 | B12: OCTUBRE | C12: 0 | D12: =CONCATENATE(B12,C12) -> OCTUBRE0 | E12: 43413 | F12: 43781 | G12: 44145 | H12: 44523 | I12: 44888 | J12: 45252 | K12: 45622 | L12: 45987 | N12: Julio - Agosto | O12: 1 | W12: Enero - Abril | X12: 3 | AF12: 9
A13: 11 | B13: NOVIEMBRE | C13: 0 | D13: =CONCATENATE(B13,C13) -> NOVIEMBRE0 | E13: 43444 | F13: 43809 | G13: 44175 | H13: 44553 | I13: 44918 | J13: 44917 | K13: 45649 | L13: 46014 | N13: Septiembre - Octubre | O13: 1 | W13: Mayo - Agosto | X13: 3
A14: 12 | B14: DICIEMBRE | C14: 0 | D14: =CONCATENATE(B14,C14) -> DICIEMBRE0 | E14: 43476 | F14: 43840 | G14: 44209 | H14: 44586 | I14: 44950 | J14: 45314 | K14: 45681 | L14: 46048 | N14: Noviembre - Diciembre | O14: 1 | W14: Septiembre - Diciembre | X14: 3
A15: 1 | B15: ENERO | C15: 1 | D15: =CONCATENATE(B15,C15) -> ENERO1 | E15: 43152 | F15: 43517 | G15: 43885 | H15: 44236 | I15: 44600 | J15: 44964 | K15: 45331 | L15: 45699 | N15: Enero - Febrero | O15: 2 | W15: Enero - Abril | X15: 4
A16: 2 | B16: FEBRERO | C16: 1 | D16: =CONCATENATE(B16,C16) -> FEBRERO1 | E16: 43181 | F16: 43545 | G16: 43914 | H16: 44264 | I16: 44628 | J16: 44992 | K16: 45362 | L16: 45727 | N16: Marzo - Abril | O16: 2 | W16: Mayo - Agosto | X16: 4
A17: 3 | B17: MARZO | C17: 1 | D17: =CONCATENATE(B17,C17) -> MARZO1 | E17: 43213 | F17: 43576 | G17: 43948 | H17: 44298 | I17: 44658 | J17: 45026 | K17: 45391 | L17: 45756 | N17: Mayo - Junio | O17: 2 | W17: Septiembre - Diciembre | X17: 4
A18: 4 | B18: ABRIL | C18: 1 | D18: =CONCATENATE(B18,C18) -> ABRIL1 | E18: 43243 | F18: 43607 | G18: 43977 | H18: 44326 | I18: 44691 | J18: 45055 | K18: 45422 | L18: 45789 | N18: Julio - Agosto | O18: 2 | W18: Enero - Abril | X18: 5
A19: 5 | B19: MAYO | C19: 1 | D19: =CONCATENATE(B19,C19) -> MAYO1 | E19: 43277 | F19: 43641 | G19: 44006 | H19: 44356 | I19: 44719 | J19: 45084 | K19: 45456 | L19: 45819 | N19: Septiembre - Octubre | O19: 2 | W19: Mayo - Agosto | X19: 5
A20: 6 | B20: JUNIO | C20: 1 | D20: =CONCATENATE(B20,C20) -> JUNIO1 | E20: 43305 | F20: 43668 | G20: 44033 | H20: 44385 | I20: 44750 | J20: 45114 | K20: 45483 | L20: 45847 | N20: Noviembre - Diciembre | O20: 2 | W20: Septiembre - Diciembre | X20: 5
A21: 7 | B21: JULIO | C21: 1 | D21: =CONCATENATE(B21,C21) -> JULIO1 | E21: 43335 | F21: 43700 | G21: 44068 | H21: 44418 | I21: 44782 | J21: 45147 | K21: 45516 | L21: 45881 | N21: Enero - Febrero | O21: 3 | W21: Enero - Abril | X21: 6
A22: 8 | B22: AGOSTO | C22: 1 | D22: =CONCATENATE(B22,C22) -> AGOSTO1 | E22: 43367 | F22: 43731 | G22: 44095 | H22: 44447 | I22: 44811 | J22: 45176 | K22: 45545 | L22: 45909 | N22: Marzo - Abril | O22: 3 | W22: Mayo - Agosto | X22: 6
A23: 9 | B23: SEPTIEMBRE | C23: 1 | D23: =CONCATENATE(B23,C23) -> SEPTIEMBRE1 | E23: 43396 | F23: 43760 | G23: 44124 | H23: 44476 | I23: 44841 | J23: 45209 | K23: 45574 | L23: 45939 | N23: Mayo - Junio | O23: 3 | W23: Septiembre - Diciembre | X23: 6
A24: 10 | B24: OCTUBRE | C24: 1 | D24: =CONCATENATE(B24,C24) -> OCTUBRE1 | E24: 43427 | F24: 43794 | G24: 44159 | H24: 44509 | I24: 44874 | J24: 45238 | K24: 45609 | L24: 45973 | N24: Julio - Agosto | O24: 3 | W24: Enero - Abril | X24: 7
... A32: 6 | B32: JUNIO | C32: 2 | D32: =CONCATENATE(B32,C32) -> JUNIO2 | E32: 43304 | F32: 43665 | G32: 44029 | H32: 44386 | I32: 44753 | J32: 45117 | K32: 45484 | L32: 45848 | N32: Noviembre - Diciembre | O32: 4 | W32: Septiembre - Diciembre | X32: 9
A33: 7 | B33: JULIO | C33: 2 | D33: =CONCATENATE(B33,C33) -> JULIO2 | E33: 43334 | F33: 43699 | G33: 44067 | H33: 44419 | I33: 44783 | J33: 45148 | K33: 45517 | L33: 45882 | N33: Enero - Febrero | O33: 5
A34: 8 | B34: AGOSTO | C34: 2 | D34: =CONCATENATE(B34,C34) -> AGOSTO2 | E34: 43364 | F34: 43728 | G34: 44092 | H34: 44448 | I34: 44812 | J34: 45177 | K34: 45546 | L34: 45910 | N34: Marzo - Abril | O34: 5
A35: 9 | B35: SEPTIEMBRE | C35: 2 | D35: =CONCATENATE(B35,C35) -> SEPTIEMBRE2 | E35: 43395 | F35: 43759 | G35: 44123 | H35: 44477 | I35: 44844 | J35: 45210 | K35: 45575 | L35: 45940 | N35: Mayo - Junio | O35: 5
A36: 10 | B36: OCTUBRE | C36: 2 | D36: =CONCATENATE(B36,C36) -> OCTUBRE2 | E36: 43426 | F36: 43791 | G36: 44158 | H36: 44510 | I36: 44875 | J36: 45239 | K36: 45610 | L36: 45974 | N36: Julio - Agosto | O36: 5
A37: 11 | B37: NOVIEMBRE | C37: 2 | D37: =CONCATENATE(B37,C37) -> NOVIEMBRE2 | E37: 43454 | F37: 43819 | G37: 44187 | H37: 44543 | I37: 44908 | J37: 45272 | K37: 45637 | L37: 46002 | N37: Septiembre - Octubre | O37: 5
A38: 12 | B38: DICIEMBRE | C38: 2 | D38: =CONCATENATE(B38,C38) -> DICIEMBRE2 | E38: 43488 | F38: 43852 | G38: 44221 | H38: 44574 | I38: 44938 | J38: 45302 | K38: 45671 | L38: 46036 | N38: Noviembre - Diciembre | O38: 5
A39: 1 | B39: ENERO | C39: 3 | D39: =CONCATENATE(B39,C39) -> ENERO3 | E39: 43150 | F39: 43515 | G39: 43881 | H39: 44238 | I39: 44602 | J39: 44966 | K39: 45335 | L39: 45701 | N39: Enero - Febrero | O39: 6
A40: 2 | B40: FEBRERO | C40: 3 | D40: =CONCATENATE(B40,C40) -> FEBRERO3 | E40: 43179 | F40: 43543 | G40: 43909 | H40: 44266 | I40: 44630 | J40: 44994 | K40: 45364 | L40: 45729 | N40: Marzo - Abril | O40: 6
A41: 3 | B41: MARZO | C41: 3 | D41: =CONCATENATE(B41,C41) -> MARZO3 | E41: 43209 | F41: 43578 | G41: 43944 | H41: 44300 | I41: 44662 | J41: 45028 | K41: 45393 | L41: 45758 | N41: Mayo - Junio | O41: 6
A42: 4 | B42: ABRIL | C42: 3 | D42: =CONCATENATE(B42,C42) -> ABRIL3 | E42: 43241 | F42: 43605 | G42: 43972 | H42: 44328 | I42: 44693 | J42: 45057 | K42: 45427 | L42: 45791 | N42: Julio - Agosto | O42: 6
A43: 5 | B43: MAYO | C43: 3 | D43: =CONCATENATE(B43,C43) -> MAYO3 | E43: 43273 | F43: 43636 | G43: 44001 | H43: 44358 | I43: 44721 | J43: 45086 | K43: 45460 | L43: 45821 | N43: Septiembre - Octubre | O43: 6
A44: 6 | B44: JUNIO | C44: 3 | D44: =CONCATENATE(B44,C44) -> JUNIO3 | E44: 43300 | F44: 43664 | G44: 44028 | H44: 44389 | I44: 44754 | J44: 45118 | K44: 45485 | L44: 45849 | N44: Noviembre - Diciembre | O44: 6
... A62: 12 | B62: DICIEMBRE | C62: 4 | D62: =CONCATENATE(B62,C62) -> DICIEMBRE4 | E62: 43486 | F62: 43850 | G62: 44217 | H62: 44578 | I62: 44942 | J62: 45306 | K62: 45673 | L62: 46038 | N62: Noviembre - Diciembre | O62: 9
A63: 1 | B63: ENERO | C63: 5 | D63: =CONCATENATE(B63,C63) -> ENERO5 | E63: 43146 | F63: 43511 | G63: 43879 | H63: 44242 | I63: 44606 | J63: 44970 | K63: 45337 | L63: 45705
A64: 2 | B64: FEBRERO | C64: 5 | D64: =CONCATENATE(B64,C64) -> FEBRERO5 | E64: 43174 | F64: 43539 | G64: 43907 | H64: 44270 | I64: 44634 | J64: 44998 | K64: 45366 | L64: 45733
...

Sheet Resoluciones de Tarifas
A1: Resolución 01299 de 2020
A2: Recaudo | E2: Aporte
B3: Cuantía | C3: Ajustado a la Centena | E3: Número de escrituras autorizadas | F3: Aporte por escritura | G3: Ajustado a la Centena | K3: 2020 | L3: 2021 | M3: 2022 | N3: 2023 | O3: 2024 | P3: 2025
A4: 1 | B4: Acto sin cuantía y escritura Excenta | C4: 13200 | E4: 1 | F4: =E5-1 -> 500 | G4: 3200 | J4: Acto sin cuantía y escritura Excenta | K4: 13200 | L4: 13600 | M4: 14300 | N4: 15900 | O4: 17400 | P4: 18400
A5: 2 | B5: De 0.00 a 100.000.000,00 | C5: 19800 | E5: 501 | F5: =E6-1 -> 1000 | G5: 4100 | J5: De 0.00 a 100.000.000,00 | K5: 19800 | L5: 20400 | M5: 21400 | N5: 23900 | O5: 26200 | P5: 27600
A6: 3 | B6: De 100.000.001,00 a 300.000.000.00 | C6: 29800 | E6: 1001 | F6: =E7-1 -> 2000 | G6: 4900 | J6: De 100.000.001,00 a 300.000.000.00 | K6: 29800 | L6: 30900 | M6: 32300 | N6: 36100 | O6: 39500 | P6: 41700
A7: 4 | B7: De 300.000.001,00 a 500.000.000,00 | C7: 36000 | E7: 2001 | F7: =E8-1 -> 3000 | G7: 5700 | J7: De 300.000.001,00 a 500.000.000,00 | K7: 36000 | L7: 37200 | M7: 39000 | N7: 43500 | O7: 47600 | P7: 50300
A8: 5 | B8: De 500.000.001,00 a 1.000.000.000,00 | C8: 49200 | E8: 3001 | F8: =E9-1 -> 4000 | G8: 6600 | J8: De 500.000.001,00 a 1.000.000.000,00 | K8: 49200 | L8: 50900 | M8: 53300 | N8: 59400 | O8: 65000 | P8: 68600
A9: 6 | B9: De 1.000.000.001,00 a 1.500.000.000,00 | C9: 57900 | E9: 4001 | F9: =E10-1 -> 5000 | G9: 8800 | J9: De 1.000.000.001,00 a 1.500.000.000,00 | K9: 57900 | L9: 60000 | M9: 62800 | N9: 70000 | O9: 76700 | P9: 80900
A10: 7 | B10: De 1.500.000.001,00 en adelante | C10: 65800 | E10: 5001 | F10: =E11-1 -> 6000 | G10: 10500 | J10: De 1.500.000.001,00 en adelante | K10: 65800 | L10: 68100 | M10: 71300 | N10: 79600 | O10: 87200 | P10: 92000
E11: 6001 | F11: =E12-1 -> 7000 | G11: 12300
E12: 7001 | F12: =E13-1 -> 8000 | G12: 14000
E13: 8001 | F13: =E14-1 -> 9000 | G13: 19300
E14: 9001 | F14: =E15-1 -> 10000 | G14: 21100
E15: 10001 | F15: =E16-1 -> 11000 | G15: 24600
E16: 11001 | F16: =E17-1 -> 12000 | G16: 28500
E17: 12001 | F17: =E18-1 -> 13000 | G17: 37300
E18: 13001 | F18: =E19-1 -> 14000 | G18: 46100
E19: 14001 | F19: =E20-1 -> 15000 | G19: 57100
E20: 15001 | F20: =E21-1 -> 16000 | G20: 74600
E21: 16001 | F21: + | G21: 92200
A22: Resolución 00536 de 2021
A23: Recaudo | E23: Aporte
B24: Cuantía | C24: Ajustado a la Centena | E24: Número de escrituras autorizadas | F24: Aporte por escritura | G24: Ajustado a la Centena
A25: 1 | B25: Acto sin cuantía y escritura Excenta | C25: 13600 | E25: 1 | F25: =E26-1 -> 500 | G25: 3400
A26: 2 | B26: De 0.00 a 100.000.000,00 | C26: 20400 | E26: 501 | F26: =E27-1 -> 1000 | G26: 4300
A27: 3 | B27: De 100.000.001,00 a 300.000.000.00 | C27: 30900 | E27: 1001 | F27: =E28-1 -> 2000 | G27: 5100
A28: 4 | B28: De 300.000.001,00 a 500.000.000,00 | C28: 37200 | E28: 2001 | F28: =E29-1 -> 3000 | G28: 5900
A29: 5 | B29: De 500.000.001,00 a 1.000.000.000,00 | C29: 50900 | E29: 3001 | F29: =E30-1 -> 4000 | G29: 6800
A30: 6 | B30: De 1.000.000.001,00 a 1.500.000.000,00 | C30: 60000 | E30: 4001 | F30: =E31-1 -> 5000 | G30: 9100
A31: 7 | B31: De 1.500.000.001,00 en adelante | C31: 68100 | E31: 5001 | F31: =E32-1 -> 6000 | G31: 10900
E32: 6001 | F32: =E33-1 -> 7000 | G32: 12700
E33: 7001 | F33: =E34-1 -> 8000 | G33: 14500
E34: 8001 | F34: =E35-1 -> 9000 | G34: 20000
E35: 9001 | F35: =E36-1 -> 10000 | G35: 21800
E36: 10001 | F36: =E37-1 -> 11000 | G36: 25400
E37: 11001 | F37: =E38-1 -> 12000 | G37: 29500
E38: 12001 | F38: =E39-1 -> 13000 | G38: 38600
E39: 13001 | F39: =E40-1 -> 14000 | G39: 47700
E40: 14001 | F40: =E41-1 -> 15000 | G40: 59100
...

Sheet Recaudo
A1: MES | C1: VALOR | D1: FECHA CONSIGNACION | F1: Tarifa Plena | G1: Tarifa Especial | I1: Escritura Inicial | J1: Escritura Final | K1: Total | M1: Valor según rango | N1: Número de escrituras | O1: Recaudado | P1: Aporte a recaudos
A2: 2019 | F2: Tarifa Plena | G2: Tarifa Especial | I2: Rango de Escrituras | N2: Número de escrituras | O2: Recaudado | P2: Aporte a recaudos
A3: MES | C3: VALOR | D3: FECHA CONSIGNACION | F3: 4600 | G3: =F3/2 -> 2300 | I3: Escritura Inicial | J3: Escritura Final | K3: Total | M3: 12400 | O3: =M3*N3 -> 0 | P3: =O3/2 -> 0
A4: Julio | E4: =IF(AND(EOMONTH(DATE($A$2,MONTH("1-"&A4&"-"&$A$2),1),0)>=Generales!$B$4,DATE($A$2,MONTH("1-"&A4&"-"&$A$2),1)<=Generales!$C$4),"","FUERA DE RANGO") -> FUERA DE RANGO | K4: =(J4-I4)+1 -> 1 | M4: 18600 | O4: =N4*M4 -> 0 | P4: =O4/2 -> 0
A5: Agosto | E5: =IF(AND(EOMONTH(DATE($A$2,MONTH("1-"&A5&"-"&$A$2),1),0)>=Generales!$B$4,DATE($A$2,MONTH("1-"&A5&"-"&$A$2),1)<=Generales!$C$4),"","FUERA DE RANGO") -> FUERA DE RANGO | I5: =J4+1 -> 1 | K5: =(J5-I5)+1 -> 0 | M5: 28200 | O5: =M5*N5 -> 0 | P5: =O5/2 -> 0
A6: Septiembre | E6: =IF(AND(EOMONTH(DATE($A$2,MONTH("1-"&A6&"-"&$A$2),1),0)>=Generales!$B$4,DATE($A$2,MONTH("1-"&A6&"-"&$A$2),1)<=Generales!$C$4),"","FUERA DE RANGO") -> FUERA DE RANGO | I6: =J5+1 -> 1 | K6: =(J6-I6)+1 -> 0 | M6: 34000 | O6: =M6*N6 -> 0 | P6: =O6/2 -> 0
A7: Octubre | E7: =IF(AND(EOMONTH(DATE($A$2,MONTH("1-"&A7&"-"&$A$2),1),0)>=Generales!$B$4,DATE($A$2,MONTH("1-"&A7&"-"&$A$2),1)<=Generales!$C$4),"","FUERA DE RANGO") -> FUERA DE RANGO | I7: =J6+1 -> 1 | K7: =(J7-I7)+1 -> 0 | M7: 46400 | O7: =M7*N7 -> 0 | P7: =O7/2 -> 0
A8: Noviembre | E8: =IF(AND(EOMONTH(DATE($A$2,MONTH("1-"&A8&"-"&$A$2),1),0)>=Generales!$B$4,DATE($A$2,MONTH("1-"&A8&"-"&$A$2),1)<=Generales!$C$4),"","FUERA DE RANGO") -> FUERA DE RANGO | I8: 1717 | K8: =(J8-I8)+1 -> -1716 | M8: 54700 | O8: =M8*N8 -> 0 | P8: =O8/2 -> 0
A9: Diciembre | E9: =IF(AND(EOMONTH(DATE($A$2,MONTH("1-"&A9&"-"&$A$2),1),0)>=Generales!$B$4,DATE($A$2,MONTH("1-"&A9&"-"&$A$2),1)<=Generales!$C$4),"","FUERA DE RANGO") -> FUERA DE RANGO | I9: =J8+1 -> 1 | K9: =(J9-I9)+1 -> 0 | M9: 62100 | O9: =M9*N9 -> 0 | P9: =O9/2 -> 0
K10: =(J10-I10)+1 -> 1 | N10: =SUM(N3:N9) -> 0 | O10: =SUM(O3:O9) -> 0 | P10: =SUM(P3:P9) -> 0
K11: =(J11-I11)+1 -> 1
A12: 2020 | K12: =(J12-I12)+1 -> 1
A13: MES | B13: BANCO | C13: VALOR | D13: FECHA CONSIGNACION | F13: =VLOOKUP(G14,'Resoluciones de Tarifas'!E4:G21,3,TRUE) -> 3200 | G13: =F13/2 -> 1600 | K13: =(J13-I13)+1 -> 1 | M13: Formato de liquidación de recaudos
A14: Enero | B14: PSE | D14: 43866 | E14: =IF(AND(EOMONTH(DATE($A$12,MONTH("1-"&A14&"-"&$A$12),1),0)>=Generales!$B$4,DATE($A$12,MONTH("1-"&A14&"-"&$A$12),1)<=Generales!$C$4),"","FUERA DE RANGO") -> FUERA DE RANGO | F14: #EP Generan Aportes Año anterior | G14: =G15-G16-G17 -> 1 | I14: 1 | K14: =(J14-I14)+1 -> 0 | M14: Año | N14: 2020
A15: Febrero | B15: PSE | D15: 43896 | E15: =IF(AND(EOMONTH(DATE($A$12,MONTH("1-"&A15&"-"&$A$12),1),0)>=Generales!$B$4,DATE($A$12,MONTH("1-"&A15&"-"&$A$12),1)<=Generales!$C$4),"","FUERA DE RANGO") -> FUERA DE RANGO | F15: Total Escrituras Autorizadas | G15: =K10 -> 1 | M15: =HLOOKUP($N$14,'Resoluciones de Tarifas'!$K$3:$P$10,2,FALSE) -> 13200 | O15: =M15*N15 -> 0 | P15: =O15/2 -> 0
A16: Febrero | B16: PSE | D16: 43896 | E16: =IF(AND(EOMONTH(DATE($A$12,MONTH("1-"&A16&"-"&$A$12),1),0)>=Generales!$B$4,DATE($A$12,MONTH("1-"&A16&"-"&$A$12),1)<=Generales!$C$4),"","FUERA DE RANGO") -> FUERA DE RANGO | F16: No computadas (parr 1. art. 48) | G16: 0 | I16: =J14+1 -> 1 | K16: =(J16-I16)+1 -> 0 | M16: =HLOOKUP($N$14,'Resoluciones de Tarifas'!$K$3:$P$10,3,FALSE) -> 19800 | O16: =M16*N16 -> 0 | P16: =O16/2 -> 0
A17: Marzo | B17: PSE | D17: 43935 | E17: =IF(AND(EOMONTH(DATE($A$12,MONTH("1-"&A17&"-"&$A$12),1),0)>=Generales!$B$4,DATE($A$12,MONTH("1-"&A17&"-"&$A$12),1)<=Generales!$C$4),"","FUERA DE RANGO") -> FUERA DE RANGO | F17: No autorizadas (otras) | G17: 0 | I17: =J16+1 -> 1 | K17: =(J17-I17)+1 -> 0 | M17: =HLOOKUP($N$14,'Resoluciones de Tarifas'!$K$3:$P$10,4,FALSE) -> 29800 | O17: =M17*N17 -> 0 | P17: =O17/2 -> 0
A18: Abril | B18: PSE | D18: 43963 | E18: =IF(AND(EOMONTH(DATE($A$12,MONTH("1-"&A18&"-"&$A$12),1),0)>=Generales!$B$4,DATE($A$12,MONTH("1-"&A18&"-"&$A$12),1)<=Generales!$C$4),"","FUERA DE RANGO") -> FUERA DE RANGO | I18: =J17+1 -> 1 | K18: =(J18-I18)+1 -> 0 | M18: =HLOOKUP($N$14,'Resoluciones de Tarifas'!$K$3:$P$10,5,FALSE) -> 36000 | O18: =M18*N18 -> 0 | P18: =O18/2 -> 0
A19: Mayo | B19: PSE | D19: 43985 | E19: =IF(AND(EOMONTH(DATE($A$12,MONTH("1-"&A19&"-"&$A$12),1),0)>=Generales!$B$4,DATE($A$12,MONTH("1-"&A19&"-"&$A$12),1)<=Generales!$C$4),"","FUERA DE RANGO") -> FUERA DE RANGO | I19: =J18+1 -> 1 | K19: =(J19-I19)+1 -> 0 | M19: =HLOOKUP($N$14,'Resoluciones de Tarifas'!$K$3:$P$10,6,FALSE) -> 49200 | O19: =M19*N19 -> 0 | P19: =O19/2 -> 0
A20: Junio | B20: PSE | D20: 44021 | E20: =IF(AND(EOMONTH(DATE($A$12,MONTH("1-"&A20&"-"&$A$12),1),0)>=Generales!$B$4,DATE($A$12,MONTH("1-"&A20&"-"&$A$12),1)<=Generales!$C$4),"","FUERA DE RANGO") -> FUERA DE RANGO | I20: =J19+1 -> 1 | K20: =(J20-I20)+1 -> 0 | M20: =HLOOKUP($N$14,'Resoluciones de Tarifas'!$K$3:$P$10,7,FALSE) -> 57900 | O20: =M20*N20 -> 0 | P20: =O20/2 -> 0
A21: Julio | B21: PSE | D21: 44054 | E21: =IF(AND(EOMONTH(DATE($A$12,MONTH("1-"&A21&"-"&$A$12),1),0)>=Generales!$B$4,DATE($A$12,MONTH("1-"&A21&"-"&$A$12),1)<=Generales!$C$4),"","FUERA DE RANGO") -> FUERA DE RANGO | I21: =J20+1 -> 1 | K21: =(J21-I21)+1 -> 0 | M21: =HLOOKUP($N$14,'Resoluciones de Tarifas'!$K$3:$P$10,8,FALSE) -> 65800 | O21: =M21*N21 -> 0 | P21: =O21/2 -> 0
A22: Agosto | B22: PSE | D22: 44084 | E22: =IF(AND(EOMONTH(DATE($A$12,MONTH("1-"&A22&"-"&$A$12),1),0)>=Generales!$B$4,DATE($A$12,MONTH("1-"&A22&"-"&$A$12),1)<=Generales!$C$4),"","FUERA DE RANGO") -> FUERA DE RANGO | I22: =J21+1 -> 1 | K22: =(J22-I22)+1 -> 0 | N22: =SUM(N15:N21) -> 0 | O22: =SUM(O15:O21) -> 0 | P22: =SUM(P15:P21) -> 0
A23: Septiembre | B23: PSE | D23: 44117 | E23: =IF(AND(EOMONTH(DATE($A$12,MONTH("1-"&A23&"-"&$A$12),1),0)>=Generales!$B$4,DATE($A$12,MONTH("1-"&A23&"-"&$A$12),1)<=Generales!$C$4),"","FUERA DE RANGO") -> FUERA DE RANGO | I23: =J22+1 -> 1 | K23: =(J23-I23)+1 -> 0
A24: Octubre | B24: PSE | D24: 44145 | E24: =IF(AND(EOMONTH(DATE($A$12,MONTH("1-"&A24&"-"&$A$12),1),0)>=Generales!$B$4,DATE($A$12,MONTH("1-"&A24&"-"&$A$12),1)<=Generales!$C$4),"","FUERA DE RANGO") -> FUERA DE RANGO | I24: =J23+1 -> 1 | K24: =(J24-I24)+1 -> 0
A25: Noviembre | B25: PSE | D25: 44175 | E25: =IF(AND(EOMONTH(DATE($A$12,MONTH("1-"&A25&"-"&$A$12),1),0)>=Generales!$B$4,DATE($A$12,MONTH("1-"&A25&"-"&$A$12),1)<=Generales!$C$4),"","FUERA DE RANGO") -> FUERA DE RANGO | I25: =J24+1 -> 1 | K25: =(J25-I25)+1 -> 0
A26: Diciembre | B26: PSE | D26: 44531 | E26: =IF(AND(EOMONTH(DATE($A$12,MONTH("1-"&A26&"-"&$A$12),1),0)>=Generales!$B$4,DATE($A$12,MONTH("1-"&A26&"-"&$A$12),1)<=Generales!$C$4),"","FUERA DE RANGO") -> FUERA DE RANGO | I26: =J25+1 -> 1 | K26: =(J26-I26)+1 -> 0
A28: 2021 | M28: Formato de liquidación de recaudos
A29: MES | B29: BANCO | C29: VALOR | D29: FECHA CONSIGNACION | F29: =VLOOKUP(G30,'Resoluciones de Tarifas'!E25:G42,3,TRUE) -> 5900 | G29: =F29/2 -> 2950 | K29: =(J29-I29)+1 -> 1 | M29: Año | N29: 2021
A30: Enero | E30: =IF(AND(EOMONTH(DATE($A$28,MONTH("1-"&A30&"-"&$A$28),1),0)>=Generales!$B$4,DATE($A$28,MONTH("1-"&A30&"-"&$A$28),1)<=Generales!$C$4),"","FUERA DE RANGO") -> FUERA DE RANGO | F30: #EP Generan Aportes Año anterior | G30: 3000 | I30: 1 | K30: =(J30-I30)+1 -> 0 | M30: =HLOOKUP($N$29,'Resoluciones de Tarifas'!$K$3:$P$10,2,FALSE) -> 13600 | O30: =M30*N30 -> 0 | P30: =O30/2 -> 0
A31: Febrero | E31: =IF(AND(EOMONTH(DATE($A$28,MONTH("1-"&A31&"-"&$A$28),1),0)>=Generales!$B$4,DATE($A$28,MONTH("1-"&A31&"-"&$A$28),1)<=Generales!$C$4),"","FUERA DE RANGO") -> FUERA DE RANGO | F31: Total Escrituras Autorizadas | G31: =K26 -> 0 | I31: =J30+1 -> 1 | K31: =(J31-I31)+1 -> 0 | M31: =HLOOKUP($N$29,'Resoluciones de Tarifas'!$K$3:$P$10,3,FALSE) -> 20400 | O31: =M31*N31 -> 0 | P31: =O31/2 -> 0
A32: Marzo | E32: =IF(AND(EOMONTH(DATE($A$28,MONTH("1-"&A32&"-"&$A$28),1),0)>=Generales!$B$4,DATE($A$28,MONTH("1-"&A32&"-"&$A$28),1)<=Generales!$C$4),"","FUERA DE RANGO") -> FUERA DE RANGO | F32: No computadas (parr 1. art. 48) | G32: 0 | I32: =J31+1 -> 1 | J32: 984 | K32: =(J32-I32)+1 -> 984 | M32: =HLOOKUP($N$29,'Resoluciones de Tarifas'!$K$3:$P$10,4,FALSE) -> 30900 | O32: =M32*N32 -> 0 | P32: =O32/2 -> 0
A33: Abril | E33: =IF(AND(EOMONTH(DATE($A$28,MONTH("1-"&A33&"-"&$A$28),1),0)>=Generales!$B$4,DATE($A$28,MONTH("1-"&A33&"-"&$A$28),1)<=Generales!$C$4),"","FUERA DE RANGO") -> FUERA DE RANGO | F33: No autorizadas (otras) | G33: 0 | I33: =J32+1 -> 985 | J33: 1336 | K33: =(J33-I33)+1 -> 352 | L33: 48 | M33: =HLOOKUP($N$29,'Resoluciones de Tarifas'!$K$3:$P$10,5,FALSE) -> 37200 | O33: =M33*N33 -> 0 | P33: =O33/2 -> 0
A34: Mayo | E34: =IF(AND(EOMONTH(DATE($A$28,MONTH("1-"&A34&"-"&$A$28),1),0)>=Generales!$B$4,DATE($A$28,MONTH("1-"&A34&"-"&$A$28),1)<=Generales!$C$4),"","FUERA DE RANGO") -> FUERA DE RANGO | I34: =J33+1 -> 1337 | J34: 1679 | K34: =(J34-I34)+1 -> 343 | L34: 40 | M34: =HLOOKUP($N$29,'Resoluciones de Tarifas'!$K$3:$P$10,6,FALSE) -> 50900 | O34: =M34*N34 -> 0 | P34: =O34/2 -> 0
A35: Junio | E35: =IF(AND(EOMONTH(DATE($A$28,MONTH("1-"&A35&"-"&$A$28),1),0)>=Generales!$B$4,DATE($A$28,MONTH("1-"&A35&"-"&$A$28),1)<=Generales!$C$4),"","FUERA DE RANGO") -> FUERA DE RANGO | I35: =J34+1 -> 1680 | J35: 2041 | K35: =(J35-I35)+1 -> 362 | L35: 23 | M35: =HLOOKUP($N$29,'Resoluciones de Tarifas'!$K$3:$P$10,7,FALSE) -> 60000 | O35: =M35*N35 -> 0 | P35: =O35/2 -> 0
A36: Julio | E36: =IF(AND(EOMONTH(DATE($A$28,MONTH("1-"&A36&"-"&$A$28),1),0)>=Generales!$B$4,DATE($A$28,MONTH("1-"&A36&"-"&$A$28),1)<=Generales!$C$4),"","FUERA DE RANGO") -> FUERA DE RANGO | I36: =J35+1 -> 2042 | J36: 2391 | K36: =(J36-I36)+1 -> 350 | L36: 27 | M36: =HLOOKUP($N$29,'Resoluciones de Tarifas'!$K$3:$P$10,8,FALSE) -> 68100 | O36: =M36*N36 -> 0 | P36: =O36/2 -> 0
A37: Agosto | E37: =IF(AND(EOMONTH(DATE($A$28,MONTH("1-"&A37&"-"&$A$28),1),0)>=Generales!$B$4,DATE($A$28,MONTH("1-"&A37&"-"&$A$28),1)<=Generales!$C$4),"","FUERA DE RANGO") -> FUERA DE RANGO | I37: =J36+1 -> 2392 | J37: 2766 | K37: =(J37-I37)+1 -> 375 | L37: 18 | N37: =SUM(N30:N36) -> 0 | O37: =SUM(O30:O36) -> 0 | P37: =SUM(P30:P36) -> 0
A38: Septiembre | E38: =IF(AND(EOMONTH(DATE($A$28,MONTH("1-"&A38&"-"&$A$28),1),0)>=Generales!$B$4,DATE($A$28,MONTH("1-"&A38&"-"&$A$28),1)<=Generales!$C$4),"","FUERA DE RANGO") -> FUERA DE RANGO | I38: =J37+1 -> 2767 | J38: 3168 | K38: =(J38-I38)+1 -> 402 | L38: 5
A39: Octubre | E39: =IF(AND(EOMONTH(DATE($A$28,MONTH("1-"&A39&"-"&$A$28),1),0)>=Generales!$B$4,DATE($A$28,MONTH("1-"&A39&"-"&$A$28),1)<=Generales!$C$4),"","FUERA DE RANGO") -> FUERA DE RANGO | I39: =J38+1 -> 3169 | J39: 3557 | K39: =(J39-I39)+1 -> 389 | L39: 13
A40: Noviembre | E40: =IF(AND(EOMONTH(DATE($A$28,MONTH("1-"&A40&"-"&$A$28),1),0)>=Generales!$B$4,DATE($A$28,MONTH("1-"&A40&"-"&$A$28),1)<=Generales!$C$4),"","FUERA DE RANGO") -> FUERA DE RANGO | I40: =J39+1 -> 3558 | J40: 3987 | K40: =(J40-I40)+1 -> 430 | L40: 31
A41: Diciembre | E41: =IF(AND(EOMONTH(DATE($A$28,MONTH("1-"&A41&"-"&$A$28),1),0)>=Generales!$B$4,DATE($A$28,MONTH("1-"&A41&"-"&$A$28),1)<=Generales!$C$4),"","FUERA DE RANGO") -> FUERA DE RANGO | I41: =J40+1 -> 3988 | K41: =(J41-I41)+1 -> -3987 | L41: 19
...

Sheet Fondo (Recaudo + Aporte)
A1: MES | B1: BANCO | C1: Recaudo | D1: Aporte | E1: VALOR | F1: FECHA CONSIGNACIÓN | H1: ¿Existen inconsistencias en la liquidación? | I1: Liquidado | J1: Tarifa Plena | K1: Tarifa Especial | L1: Exentas de aportes + No autorizadas | N1: ¿Coincide con el rango reportado?
A2: Julio | B2: =Recaudo!B4 -> 0 | C2: =Recaudo!C4 -> 0 | E2: =IF(C2="FUERA DE RANGO","FUERA DE RANGO",C2+D2) -> 0 | F2: =Recaudo!D4 -> 0 | G2: =Recaudo!E4 -> FUERA DE RANGO | H2: =IF(D2<I2,D2-I2,"NO") -> -23000 | I2: =((Recaudo!F3*J2)+(Recaudo!G3*K2)) -> 23000 | J2: 5 | K2: 0 | L2: 0 | M2: =K2+J2 -> 5 | N2: =IF('Fondo (Recaudo + Aporte)'!M2+L2=Recaudo!K3,"SÍ","NO") -> NO
A3: Agosto | B3: =Recaudo!B5 -> 0 | C3: =Recaudo!C5 -> 0 | E3: =IF(C3="FUERA DE RANGO","FUERA DE RANGO",C3+D3) -> 0 | F3: =Recaudo!D5 -> 0 | G3: =Recaudo!E5 -> FUERA DE RANGO | H3: =IF(D3<I3,D3-I3,"NO") -> NO | I3: =((Recaudo!F4*J3)+(Recaudo!G4*K3)) -> 0 | J3: 5 | K3: 0 | L3: 0 | M3: =K3+J3 -> 5 | N3: =IF('Fondo (Recaudo + Aporte)'!M3+L3=Recaudo!K4,"SÍ","NO") -> NO
A4: Septiembre | B4: =Recaudo!B6 -> 0 | C4: =Recaudo!C6 -> 0 | E4: =IF(C4="FUERA DE RANGO","FUERA DE RANGO",C4+D4) -> 0 | F4: =Recaudo!D6 -> 0 | G4: =Recaudo!E6 -> FUERA DE RANGO | H4: =IF(D4<I4,D4-I4,"NO") -> NO | I4: =((Recaudo!F5*J4)+(Recaudo!G5*K4)) -> 0 | J4: 5 | K4: 0 | L4: 0 | M4: =K4+J4 -> 5 | N4: =IF('Fondo (Recaudo + Aporte)'!M4+L4=Recaudo!K5,"SÍ","NO") -> NO
A5: Octubre | B5: =Recaudo!B7 -> 0 | C5: =Recaudo!C7 -> 0 | E5: =IF(C5="FUERA DE RANGO","FUERA DE RANGO",C5+D5) -> 0 | F5: =Recaudo!D7 -> 0 | G5: =Recaudo!E7 -> FUERA DE RANGO | H5: =IF(D5<I5,D5-I5,"NO") -> NO | I5: =((Recaudo!F6*J5)+(Recaudo!G6*K5)) -> 0 | J5: 5 | K5: 0 | L5: 0 | M5: =K5+J5 -> 5 | N5: =IF('Fondo (Recaudo + Aporte)'!M5+L5=Recaudo!K6,"SÍ","NO") -> NO
A6: Noviembre | B6: =Recaudo!B8 -> 0 | C6: =Recaudo!C8 -> 0 | E6: =IF(C6="FUERA DE RANGO","FUERA DE RANGO",C6+D6) -> 0 | F6: =Recaudo!D8 -> 0 | G6: =Recaudo!E8 -> FUERA DE RANGO | H6: =IF(D6<I6,D6-I6,"NO") -> NO | I6: =((Recaudo!F7*J6)+(Recaudo!G7*K6)) -> 0 | J6: 5 | K6: 0 | L6: 0 | M6: =K6+J6 -> 5 | N6: =IF('Fondo (Recaudo + Aporte)'!M6+L6=Recaudo!K7,"SÍ","NO") -> NO
A7: Diciembre | B7: =Recaudo!B9 -> 0 | C7: =Recaudo!C9 -> 0 | E7: =IF(C7="FUERA DE RANGO","FUERA DE RANGO",C7+D7) -> 0 | F7: =Recaudo!D9 -> 0 | G7: =Recaudo!E9 -> FUERA DE RANGO | H7: =IF(D7<I7,D7-I7,"NO") -> NO | I7: =((Recaudo!F8*J7)+(Recaudo!G8*K7)) -> 0 | J7: 5 | K7: 0 | L7: 0 | M7: =K7+J7 -> 5 | N7: =IF('Fondo (Recaudo + Aporte)'!M7+L7=Recaudo!K8,"SÍ","NO") -> NO
A11: AÑO 2020 | B11: BANCO | C11: Recaudo | D11: Aporte | E11: VALOR | F11: FECHA CONSIGNACIÓN
A12: MES
A13: Enero | B13: =Recaudo!B14 -> PSE | E13: =IF(C13="FUERA DE RANGO","FUERA DE RANGO",C13+D13) -> 0 | F13: =Recaudo!D14 -> 43866 | G13: =Recaudo!E14 -> FUERA DE RANGO | H13: =IF(D13<I13,D13-I13,"NO") -> NO | I13: =((Recaudo!$F$13*J13)+(Recaudo!$G$13*K13)) -> 0 | N13: =IF('Fondo (Recaudo + Aporte)'!M13+L13=Recaudo!K14,"SÍ","NO") -> SÍ
A14: Febrero | B14: PSE | E14: =IF(C14="FUERA DE RANGO","FUERA DE RANGO",C14+D14) -> 0 | F14: =Recaudo!D15 -> 43896 | G14: =Recaudo!E15 -> FUERA DE RANGO | H14: =IF(D14<I14,D14-I14,"NO") -> NO | I14: =((Recaudo!$F$13*J14)+(Recaudo!$G$13*K14)) -> 0 | M14: =K14+J14 -> 0 | N14: =IF('Fondo (Recaudo + Aporte)'!M14+L14=Recaudo!K15,"SÍ","NO") -> SÍ | Q14: =P14+O14 -> 0 | S14: 931900 | T14: 1406150 | U14: =T14+S14 -> 2338050
A15: Febrero | B15: =Recaudo!B16 -> PSE | E15: =IF(C15="FUERA DE RANGO","FUERA DE RANGO",C15+D15) -> 0 | F15: =Recaudo!D16 -> 43896 | G15: =Recaudo!E16 -> FUERA DE RANGO | H15: =IF(D15<I15,D15-I15,"NO") -> NO | I15: =((Recaudo!$F$13*J15)+(Recaudo!$G$13*K15)) -> 0 | M15: =K15+J15 -> 0 | N15: =IF('Fondo (Recaudo + Aporte)'!M15+L15=Recaudo!K16,"SÍ","NO") -> SÍ
A16: Marzo | B16: =Recaudo!B17 -> PSE | C16: =Recaudo!C17 -> 0 | E16: =IF(C16="FUERA DE RANGO","FUERA DE RANGO",C16+D16) -> 0 | F16: =Recaudo!D17 -> 43935 | G16: =Recaudo!E17 -> FUERA DE RANGO | H16: =IF(D16<I16,D16-I16,"NO") -> NO | I16: =((Recaudo!$F$13*J16)+(Recaudo!$G$13*K16)) -> 0 | M16: =K16+J16 -> 0 | N16: =IF('Fondo (Recaudo + Aporte)'!M16+L16=Recaudo!K17,"SÍ","NO") -> SÍ
A17: Abril | B17: =Recaudo!B18 -> PSE | C17: =Recaudo!C33 -> 0 | D17: =E17-C17 -> 5898800 | E17: 5898800 | F17: =Recaudo!D33 -> 0 | G17: =Recaudo!E18 -> FUERA DE RANGO | H17: =IF(D17<I17,D17-I17,"NO") -> NO | I17: =((Recaudo!F29*J17)+(Recaudo!$G$29*K17)) -> 0 | M17: =K17+J17 -> 0 | N17: =IF('Fondo (Recaudo + Aporte)'!M17+L17=Recaudo!K18,"SÍ","NO") -> SÍ
A18: Mayo | B18: =Recaudo!B19 -> PSE | C18: =Recaudo!C34 -> 0 | E18: =IF(C18="FUERA DE RANGO","FUERA DE RANGO",C18+D18) -> 0 | F18: =Recaudo!D19 -> 43985 | G18: =Recaudo!E19 -> FUERA DE RANGO | H18: =IF(D18<I18,D18-I18,"NO") -> NO | I18: =((Recaudo!$F$13*J18)+(Recaudo!$G$13*K18)) -> 0 | M18: =K18+J18 -> 0 | N18: =IF('Fondo (Recaudo + Aporte)'!M18+L18=Recaudo!K19,"SÍ","NO") -> SÍ
A19: Junio | B19: =Recaudo!B20 -> PSE | C19: =Recaudo!C35 -> 0 | E19: =IF(C19="FUERA DE RANGO","FUERA DE RANGO",C19+D19) -> 0 | F19: =Recaudo!D20 -> 44021 | G19: =Recaudo!E20 -> FUERA DE RANGO | H19: =IF(D19<I19,D19-I19,"NO") -> NO | I19: =((Recaudo!$F$13*J19)+(Recaudo!$G$13*K19)) -> 0 | M19: =K19+J19 -> 0 | N19: =IF('Fondo (Recaudo + Aporte)'!M19+L19=Recaudo!K20,"SÍ","NO") -> SÍ
A20: Julio | B20: =Recaudo!B21 -> PSE | C20: =Recaudo!C36 -> 0 | E20: =IF(C20="FUERA DE RANGO","FUERA DE RANGO",C20+D20) -> 0 | F20: =Recaudo!D21 -> 44054 | G20: =Recaudo!E21 -> FUERA DE RANGO | H20: =IF(D20<I20,D20-I20,"NO") -> NO | I20: =((Recaudo!$F$13*J20)+(Recaudo!$G$13*K20)) -> 0 | M20: =K20+J20 -> 0 | N20: =IF('Fondo (Recaudo + Aporte)'!M20+L20=Recaudo!K21,"SÍ","NO") -> SÍ
A21: Agosto | B21: =Recaudo!B22 -> PSE | C21: =Recaudo!C37 -> 0 | E21: =IF(C21="FUERA DE RANGO","FUERA DE RANGO",C21+D21) -> 0 | F21: =Recaudo!D22 -> 44084 | G21: =Recaudo!E22 -> FUERA DE RANGO | H21: =IF(D21<I21,D21-I21,"NO") -> NO | I21: =((Recaudo!$F$13*J21)+(Recaudo!$G$13*K21)) -> 0 | M21: =K21+J21 -> 0 | N21: =IF('Fondo (Recaudo + Aporte)'!M21+L21=Recaudo!K22,"SÍ","NO") -> SÍ
A22: Septiembre | B22: =Recaudo!B23 -> PSE | C22: =Recaudo!C38 -> 0 | E22: =IF(C22="FUERA DE RANGO","FUERA DE RANGO",C22+D22) -> 0 | F22: =Recaudo!D23 -> 44117 | G22: =Recaudo!E23 -> FUERA DE RANGO | H22: =IF(D22<I22,D22-I22,"NO") -> NO | I22: =((Recaudo!$F$13*J22)+(Recaudo!$G$13*K22)) -> 0 | M22: =K22+J22 -> 0 | N22: =IF('Fondo (Recaudo + Aporte)'!M22+L22=Recaudo!K23,"SÍ","NO") -> SÍ
A23: Octubre | B23: =Recaudo!B24 -> PSE | C23: =Recaudo!C39 -> 0 | E23: =IF(C23="FUERA DE RANGO","FUERA DE RANGO",C23+D23) -> 0 | F23: =Recaudo!D24 -> 44145 | G23: =Recaudo!E24 -> FUERA DE RANGO | H23: =IF(D23<I23,D23-I23,"NO") -> NO | I23: =((Recaudo!$F$13*J23)+(Recaudo!$G$13*K23)) -> 0 | M23: =K23+J23 -> 0 | N23: =IF('Fondo (Recaudo + Aporte)'!M23+L23=Recaudo!K24,"SÍ","NO") -> SÍ
A24: Noviembre | B24: =Recaudo!B25 -> PSE | C24: =Recaudo!C40 -> 0 | E24: =IF(C24="FUERA DE RANGO","FUERA DE RANGO",C24+D24) -> 0 | F24: =Recaudo!D25 -> 44175 | G24: =Recaudo!E25 -> FUERA DE RANGO | H24: =IF(D24<I24,D24-I24,"NO") -> NO | I24: =((Recaudo!$F$13*J24)+(Recaudo!$G$13*K24)) -> 0 | M24: =K24+J24 -> 0 | N24: =IF('Fondo (Recaudo + Aporte)'!M24+L24=Recaudo!K25,"SÍ","NO") -> SÍ
A25: Diciembre | B25: =Recaudo!B26 -> PSE | C25: =Recaudo!C41 -> 0 | E25: =IF(C25="FUERA DE RANGO","FUERA DE RANGO",C25+D25) -> 0 | F25: =Recaudo!D26 -> 44531 | G25: =Recaudo!E26 -> FUERA DE RANGO | H25: =IF(D25<I25,D25-I25,"NO") -> NO | I25: =((Recaudo!$F$13*J25)+(Recaudo!$G$13*K25)) -> 0 | M25: =K25+J25 -> 0 | N25: =IF('Fondo (Recaudo + Aporte)'!M25+L25=Recaudo!K26,"SÍ","NO") -> SÍ
A27: AÑO 2021 | B27: BANCO | C27: Recaudo | D27: Aporte | E27: VALOR | F27: FECHA CONSIGNACIÓN
A28: MES
A29: Enero | B29: =Recaudo!B30 -> 0 | C29: =Recaudo!C30 -> 0 | E29: =IF(C29="FUERA DE RANGO","FUERA DE RANGO",C29+D29) -> 0 | F29: =Recaudo!D30 -> 0 | G29: =Recaudo!E30 -> FUERA DE RANGO | H29: =IF(D29<I29,D29-I29,"NO") -> NO | I29: =((Recaudo!$F$29*J29)+(Recaudo!$G$29*K29)) -> 0 | M29: =K29+J29 -> 0 | N29: =IF('Fondo (Recaudo + Aporte)'!M29+L29=Recaudo!K30,"SÍ","NO") -> SÍ
A30: Febrero | B30: =Recaudo!B31 -> 0 | C30: =Recaudo!C31 -> 0 | E30: =IF(C30="FUERA DE RANGO","FUERA DE RANGO",C30+D30) -> 0 | F30: =Recaudo!D31 -> 0 | G30: =Recaudo!E31 -> FUERA DE RANGO | H30: =IF(D30<I30,D30-I30,"NO") -> NO | I30: =((Recaudo!$F$29*J30)+(Recaudo!$G$29*K30)) -> 0 | M30: =K30+J30 -> 0 | N30: =IF('Fondo (Recaudo + Aporte)'!M30+L30=Recaudo!K31,"SÍ","NO") -> SÍ
A31: Marzo | B31: =Recaudo!B32 -> 0 | C31: =Recaudo!C32 -> 0 | E31: =IF(C31="FUERA DE RANGO","FUERA DE RANGO",C31+D31) -> 0 | F31: =Recaudo!D32 -> 0 | G31: =Recaudo!E32 -> FUERA DE RANGO | H31: =IF(D31<I31,D31-I31,"NO") -> NO | I31: =((Recaudo!$F$29*J31)+(Recaudo!$G$29*K31)) -> 0 | M31: =K31+J31 -> 0 | N31: =IF('Fondo (Recaudo + Aporte)'!M31+L31=Recaudo!K32,"SÍ","NO") -> NO
A32: Abril | B32: =Recaudo!B33 -> 0 | C32: =Recaudo!C33 -> 0 | E32: 5898800 | F32: =Recaudo!D33 -> 0 | G32: =Recaudo!E33 -> FUERA DE RANGO | H32: =IF(D32<I32,D32-I32,"NO") -> NO | I32: =((Recaudo!$F$29*J32)+(Recaudo!$G$29*K32)) -> 0 | M32: =K32+J32 -> 0 | N32: =IF('Fondo (Recaudo + Aporte)'!M32+L32=Recaudo!K33,"SÍ","NO") -> NO
A33: Mayo | B33: =Recaudo!B34 -> 0 | C33: =Recaudo!C34 -> 0 | E33: =IF(C33="FUERA DE RANGO","FUERA DE RANGO",C33+D33) -> 0 | F33: =Recaudo!D34 -> 0 | G33: =Recaudo!E34 -> FUERA DE RANGO | H33: =IF(D33<I33,D33-I33,"NO") -> NO | I33: =((Recaudo!$F$29*J33)+(Recaudo!$G$29*K33)) -> 0 | M33: =K33+J33 -> 0 | N33: =IF('Fondo (Recaudo + Aporte)'!M33+L33=Recaudo!K34,"SÍ","NO") -> NO
A34: Junio | B34: =Recaudo!B35 -> 0 | C34: =Recaudo!C35 -> 0 | E34: =IF(C34="FUERA DE RANGO","FUERA DE RANGO",C34+D34) -> 0 | F34: =Recaudo!D35 -> 0 | G34: =Recaudo!E35 -> FUERA DE RANGO | H34: =IF(D34<I34,D34-I34,"NO") -> NO | I34: =((Recaudo!$F$29*J34)+(Recaudo!$G$29*K34)) -> 0 | M34: =K34+J34 -> 0 | N34: =IF('Fondo (Recaudo + Aporte)'!M34+L34=Recaudo!K35,"SÍ","NO") -> NO
A35: Julio | B35: =Recaudo!B36 -> 0 | C35: =Recaudo!C36 -> 0 | E35: =IF(C35="FUERA DE RANGO","FUERA DE RANGO",C35+D35) -> 0 | F35: =Recaudo!D36 -> 0 | G35: =Recaudo!E36 -> FUERA DE RANGO | H35: =IF(D35<I35,D35-I35,"NO") -> NO | I35: =((Recaudo!$F$29*J35)+(Recaudo!$G$29*K35)) -> 0 | M35: =K35+J35 -> 0 | N35: =IF('Fondo (Recaudo + Aporte)'!M35+L35=Recaudo!K36,"SÍ","NO") -> NO
A36: Agosto | B36: =Recaudo!B37 -> 0 | C36: =Recaudo!C37 -> 0 | E36: =IF(C36="FUERA DE RANGO","FUERA DE RANGO",C36+D36) -> 0 | F36: =Recaudo!D37 -> 0 | G36: =Recaudo!E37 -> FUERA DE RANGO | H36: =IF(D36<I36,D36-I36,"NO") -> NO | I36: =((Recaudo!$F$29*J36)+(Recaudo!$G$29*K36)) -> 0 | M36: =K36+J36 -> 0 | N36: =IF('Fondo (Recaudo + Aporte)'!M36+L36=Recaudo!K37,"SÍ","NO") -> NO
A37: Septiembre | B37: =Recaudo!B38 -> 0 | C37: =Recaudo!C38 -> 0 | E37: =IF(C37="FUERA DE RANGO","FUERA DE RANGO",C37+D37) -> 0 | F37: =Recaudo!D38 -> 0 | G37: =Recaudo!E38 -> FUERA DE RANGO | H37: =IF(D37<I37,D37-I37,"NO") -> NO | I37: =((Recaudo!$F$29*J37)+(Recaudo!$G$29*K37)) -> 0 | M37: =K37+J37 -> 0 | N37: =IF('Fondo (Recaudo + Aporte)'!M37+L37=Recaudo!K38,"SÍ","NO") -> NO
A38: Octubre | B38: =Recaudo!B39 -> 0 | C38: =Recaudo!C39 -> 0 | E38: =IF(C38="FUERA DE RANGO","FUERA DE RANGO",C38+D38) -> 0 | F38: =Recaudo!D39 -> 0 | G38: =Recaudo!E39 -> FUERA DE RANGO | H38: =IF(D38<I38,D38-I38,"NO") -> NO | I38: =((Recaudo!$F$29*J38)+(Recaudo!$G$29*K38)) -> 0 | M38: =K38+J38 -> 0 | N38: =IF('Fondo (Recaudo + Aporte)'!M38+L38=Recaudo!K39,"SÍ","NO") -> NO
A39: Noviembre | B39: =Recaudo!B40 -> 0 | C39: =Recaudo!C40 -> 0 | E39: =IF(C39="FUERA DE RANGO","FUERA DE RANGO",C39+D39) -> 0 | F39: =Recaudo!D40 -> 0 | G39: =Recaudo!E40 -> FUERA DE RANGO | H39: =IF(D39<I39,D39-I39,"NO") -> NO | I39: =((Recaudo!$F$29*J39)+(Recaudo!$G$29*K39)) -> 0 | M39: =K39+J39 -> 0 | N39: =IF('Fondo (Recaudo + Aporte)'!M39+L39=Recaudo!K40,"SÍ","NO") -> NO
A40: Diciembre | B40: =Recaudo!B41 -> 0 | C40: =Recaudo!C41 -> 0 | E40: =IF(C40="FUERA DE RANGO","FUERA DE RANGO",C40+D40) -> 0 | F40: =Recaudo!D41 -> 0 | G40: =Recaudo!E41 -> FUERA DE RANGO | H40: =IF(D40<I40,D40-I40,"NO") -> NO | I40: =((Recaudo!$F$29*J40)+(Recaudo!$G$29*K40)) -> 0 | M40: =K40+J40 -> 0 | N40: =IF('Fondo (Recaudo + Aporte)'!M40+L40=Recaudo!K41,"SÍ","NO") -> NO
A42: AÑO 2022 | B42: BANCO | C42: Recaudo | D42: Aporte | E42: VALOR | F42: FECHA CONSIGNACIÓN
A43: MES
A44: Enero | B44: =Recaudo!B45 -> 0 | C44: =Recaudo!C45 -> 0 | E44: =IF(C44="FUERA DE RANGO","FUERA DE RANGO",C44+D44) -> 0 | F44: =Recaudo!D45 -> 0 | G44: =Recaudo!E45 -> FUERA DE RANGO | H44: =IF(D44<I44,D44-I44,"NO") -> NO | I44: =((Recaudo!$F$29*J44)+(Recaudo!$G$29*K44)) -> 0 | M44: =K44+J44 -> 0 | N44: =IF('Fondo (Recaudo + Aporte)'!M44+L44=Recaudo!K45,"SÍ","NO") -> SÍ
A45: Febrero | B45: =Recaudo!B46 -> 0 | C45: =Recaudo!C46 -> 0 | E45: =IF(C45="FUERA DE RANGO","FUERA DE RANGO",C45+D45) -> 0 | F45: =Recaudo!D46 -> 0 | G45: =Recaudo!E46 -> FUERA DE RANGO | H45: =IF(D45<I45,D45-I45,"NO") -> #N/A | I45: =((Recaudo!$F$44*J45)+(Recaudo!$G$44*K45)) -> #N/A | M45: =K45+J45 -> 0 | N45: =IF('Fondo (Recaudo + Aporte)'!M45+L45=Recaudo!K46,"SÍ","NO") -> SÍ
...

Sheet Admin. Justicia
A2: AÑO 2017
A3: MES | B3: BANCO | C3: VALOR | D3: FECHA CONSIGNACION | F3: CUMPLE | G3: OBSERVACIONES
A4: Junio
A5: Julio
A6: Agosto
A7: Septiembre
A8: Octubre
A9: Noviembre
A10: Diciembre
A13: MES | B13: BANCO | C13: VALOR | D13: FECHA CONSIGNACIÓN | E13: FECHA DE OBLIGACIÓN | F13: CUMPLE | G13: OBSERVACIONES | H13: INGRESOS BRUTOS | I13: ING. EXCLUIDOS | J13: 0.125
A14: Julio | E14: 43685 | F14: =IF(E14>=D14,"CUMPLE","NO CUMPLE") -> CUMPLE | G14: Ninguna | J14: =(H14-I14)*12.5% -> 0
A15: Agosto | E15: 43714 | F15: =IF(E15>=D15,"CUMPLE","NO CUMPLE") -> CUMPLE | G15: Ninguna | J15: =(H15-I15)*12.5% -> 0
A16: Septiembre | E16: 43745 | F16: =IF(E16>=D16,"CUMPLE","NO CUMPLE") -> CUMPLE | G16: Ninguna | J16: =(H16-I16)*12.5% -> 0
A17: Octubre | E17: 43777 | F17: =IF(E17>=D17,"CUMPLE","NO CUMPLE") -> CUMPLE | G17: Ninguna | J17: =(H17-I17)*12.5% -> 0
A18: Noviembre | E18: 43805 | F18: =IF(E18>=D18,"CUMPLE","NO CUMPLE") -> CUMPLE | G18: Ninguna | J18: =(H18-I18)*12.5% -> 0
A19: Diciembre | E19: 43839 | F19: =IF(E19>=D19,"CUMPLE","NO CUMPLE") -> CUMPLE | G19: Ninguna | J19: =(H19-I19)*12.5% -> 0
A21: AÑO 2020
A22: MES | B22: BANCO | C22: VALOR | D22: FECHA CONSIGNACIÓN | E22: FECHA DE OBLIGACIÓN | F22: CUMPLE | G22: OBSERVACIONES
A23: Enero | E23: 43868 | F23: CUMPLE | G23: Ninguna | J23: =(H23-I23)*12.5% -> 0
A24: Febrero | E24: 43896 | F24: CUMPLE | G24: Ninguna | J24: =(H24-I24)*12.5% -> 0
A25: Marzo | E25: 43928 | F25: =IF(E25>=D25,"CUMPLE","NO CUMPLE") -> CUMPLE | G25: Ninguna | J25: =(H25-I25)*12.5% -> 0
A26: Abril | E26: 43959 | F26: =IF(E26>=D26,"CUMPLE","NO CUMPLE") -> CUMPLE | G26: Ninguna | J26: =(H26-I26)*12.5% -> 0
A27: Mayo | E27: 43987 | F27: =IF(E27>=D27,"CUMPLE","NO CUMPLE") -> CUMPLE | G27: Ninguna | J27: =(H27-I27)*12.5% -> 0
A28: Junio | E28: 44019 | F28: =IF(E28>=D28,"CUMPLE","NO CUMPLE") -> CUMPLE | G28: Ninguna | J28: =(H28-I28)*12.5% -> 0
A29: Julio | E29: 44053 | F29: =IF(E29>=D29,"CUMPLE","NO CUMPLE") -> CUMPLE | G29: Ninguna | J29: =(H29-I29)*12.5% -> 0
A30: Agosto | E30: 44081 | F30: =IF(E30>=D30,"CUMPLE","NO CUMPLE") -> CUMPLE | G30: Ninguna | J30: =(H30-I30)*12.5% -> 0
A31: Septiembre | E31: 44111 | F31: =IF(E31>=D31,"CUMPLE","NO CUMPLE") -> CUMPLE | G31: Ninguna | J31: =(H31-I31)*12.5% -> 0
A32: Octubre | E32: 44144 | F32: =IF(E32>=D32,"CUMPLE","NO CUMPLE") -> CUMPLE | G32: Ninguna | J32: =(H32-I32)*12.5% -> 0
A33: Noviembre | E33: 44172 | F33: =IF(E33>=D33,"CUMPLE","NO CUMPLE") -> CUMPLE | G33: Ninguna | J33: =(H33-I33)*12.5% -> 0
A34: Diciembre | E34: 44204 | F34: =IF(E34>=D34,"CUMPLE","NO CUMPLE") -> CUMPLE | G34: Ninguna | J34: =(H34-I34)*12.5% -> 0
A36: AÑO 2021
A37: MES | B37: BANCO | C37: VALOR | D37: FECHA CONSIGNACIÓN | E37: FECHA DE OBLIGACIÓN | F37: CUMPLE | G37: OBSERVACIONES
A38: Enero | E38: 44232 | F38: =IF(E38>=D38,"CUMPLE","NO CUMPLE") -> CUMPLE | G38: Ninguna | J38: =(H38-I38)*12.5% -> 0
A39: Febrero | E39: 44260 | F39: =IF(E39>=D39,"CUMPLE","NO CUMPLE") -> CUMPLE | G39: Ninguna | J39: =(H39-I39)*12.5% -> 0
A40: Marzo | E40: 44295 | F40: =IF(E40>=D40,"CUMPLE","NO CUMPLE") -> CUMPLE | G40: Ninguna | J40: =(H40-I40)*12.5% -> 0
A41: Abril | E41: 44323 | F41: =IF(E41>=D41,"CUMPLE","NO CUMPLE") -> CUMPLE | G41: Ninguna | J41: =(H41-I41)*12.5% -> 0
A42: Mayo | E42: 44355 | F42: =IF(E42>=D42,"CUMPLE","NO CUMPLE") -> CUMPLE | G42: Ninguna | J42: =(H42-I42)*12.5% -> 0
A43: Junio | E43: 44385 | F43: =IF(E43>=D43,"CUMPLE","NO CUMPLE") -> CUMPLE | G43: Ninguna | J43: =(H43-I43)*12.5% -> 0
A44: Julio | E44: 44414 | F44: =IF(E44>=D44,"CUMPLE","NO CUMPLE") -> CUMPLE | G44: Ninguna | J44: =(H44-I44)*12.5% -> 0
A45: Agosto | E45: 44446 | F45: =IF(E45>=D45,"CUMPLE","NO CUMPLE") -> CUMPLE | G45: Ninguna | J45: =(H45-I45)*12.5% -> 0
...

Sheet 10% RC
A2: AÑO 2019
A3: MES | B3: BANCO | C3: VALOR | D3: FECHA CONSIGNACION | E3: FECHA ENVIO
A4: Julio | E4: =D4 -> 0
A5: Agosto | E5: =D5 -> 0
A6: Septiembre | E6: =D6 -> 0
A7: Octubre | E7: =D7 -> 0
A8: Noviembre | E8: =D8 -> 0
A9: Diciembre | E9: =D9 -> 0
A11: AÑO 2020
A12: MES | B12: BANCO | C12: VALOR | D12: FECHA CONSIGNACION | E12: FECHA ENVIO
A13: Enero | E13: =D13 -> 0
A14: Febrero | E14: =D14 -> 0
A15: Marzo | E15: =D15 -> 0
A16: Abril | E16: =D16 -> 0
A17: Mayo | E17: =D17 -> 0
A18: Junio | E18: =D18 -> 0
A19: Julio | E19: =D19 -> 0
A20: Agosto | E20: =D20 -> 0
A21: Septiembre | E21: =D21 -> 0
A22: Octubre | E22: =D22 -> 0
A23: Noviembre | E23: =D23 -> 0
A24: Diciembre | E24: =D24 -> 0
A26: AÑO 2021
A27: MES | B27: BANCO | C27: VALOR | D27: FECHA CONSIGNACION | E27: FECHA ENVIO
A28: Enero | E28: =D28 -> 0
A29: Febrero | E29: =D29 -> 0
A30: Marzo | E30: =D30 -> 0
A31: Abril | E31: =D31 -> 0
A32: Mayo | E32: =D32 -> 0
A33: Junio | E33: =D33 -> 0
A34: Julio | E34: =D34 -> 0
A35: Agosto | E35: =D35 -> 0
A36: Septiembre | E36: =D36 -> 0
A37: Octubre | E37: =D37 -> 0
A38: Noviembre | E38: =D38 -> 0
A39: Diciembre | E39: =D39 -> 0
A41: AÑO 2022
A42: MES | B42: BANCO | C42: VALOR | D42: FECHA CONSIGNACION | E42: FECHA ENVIO
A43: Enero | E43: =D43 -> 0
A44: Febrero | E44: =D44 -> 0
...

Sheet Retefuente
A1: ÚLTIMO DÍGITO CC | C1: 9
A4: 2019
A5: MES | C5: BANCO | D5: VALOR | E5: FECHA CONSIGNACION | F5: FECHA PAGO SEGÚN CALENDARIO TRIBUTARIO | G5: DIAS INCUMPLIDOS
A6: Julio | B6: =CONCATENATE(A6,$C$1) -> Julio9 | F6: =VLOOKUP(B6,'Calendario Tributario'!$D$3:$K$122,3,0) -> 43689 | G6: =IF(E6-F6>0,E6-F6,0) -> 0 | H6: =IF(AND(EOMONTH(DATE($A$4,MONTH("1-"&A6&"-"&$A$4),1),0)>=Generales!$B$4,DATE($A$4,MONTH("1-"&A6&"-"&$A$4),1)<=Generales!$C$4),"","FUERA DE RANGO") -> FUERA DE RANGO
A7: Agosto | B7: =CONCATENATE(A7,$C$1) -> Agosto9 | F7: =VLOOKUP(B7,'Calendario Tributario'!$D$3:$K$122,3,0) -> 43719 | G7: =IF(E7-F7>0,E7-F7,0) -> 0 | H7: =IF(AND(EOMONTH(DATE($A$4,MONTH("1-"&A7&"-"&$A$4),1),0)>=Generales!$B$4,DATE($A$4,MONTH("1-"&A7&"-"&$A$4),1)<=Generales!$C$4),"","FUERA DE RANGO") -> FUERA DE RANGO
A8: Septiembre | B8: =CONCATENATE(A8,$C$1) -> Septiembre9 | F8: =VLOOKUP(B8,'Calendario Tributario'!$D$3:$K$122,3,0) -> 43747 | G8: =IF(E8-F8>0,E8-F8,0) -> 0 | H8: =IF(AND(EOMONTH(DATE($A$4,MONTH("1-"&A8&"-"&$A$4),1),0)>=Generales!$B$4,DATE($A$4,MONTH("1-"&A8&"-"&$A$4),1)<=Generales!$C$4),"","FUERA DE RANGO") -> FUERA DE RANGO
A9: Octubre | B9: =CONCATENATE(A9,$C$1) -> Octubre9 | F9: =VLOOKUP(B9,'Calendario Tributario'!$D$3:$K$122,3,0) -> 43782 | G9: =IF(E9-F9>0,E9-F9,0) -> 0 | H9: =IF(AND(EOMONTH(DATE($A$4,MONTH("1-"&A9&"-"&$A$4),1),0)>=Generales!$B$4,DATE($A$4,MONTH("1-"&A9&"-"&$A$4),1)<=Generales!$C$4),"","FUERA DE RANGO") -> FUERA DE RANGO
A10: Noviembre | B10: =CONCATENATE(A10,$C$1) -> Noviembre9 | F10: =VLOOKUP(B10,'Calendario Tributario'!$D$3:$K$122,3,0) -> 43810 | G10: =IF(E10-F10>0,E10-F10,0) -> 0 | H10: =IF(AND(EOMONTH(DATE($A$4,MONTH("1-"&A10&"-"&$A$4),1),0)>=Generales!$B$4,DATE($A$4,MONTH("1-"&A10&"-"&$A$4),1)<=Generales!$C$4),"","FUERA DE RANGO") -> FUERA DE RANGO
A11: Diciembre | B11: =CONCATENATE(A11,$C$1) -> Diciembre9 | F11: =VLOOKUP(B11,'Calendario Tributario'!$D$3:$K$122,3,0) -> 43843 | G11: =IF(E11-F11>0,E11-F11,0) -> 0 | H11: =IF(AND(EOMONTH(DATE($A$4,MONTH("1-"&A11&"-"&$A$4),1),0)>=Generales!$B$4,DATE($A$4,MONTH("1-"&A11&"-"&$A$4),1)<=Generales!$C$4),"","FUERA DE RANGO") -> FUERA DE RANGO
A13: 2020
A14: MES | C14: BANCO | D14: VALOR | E14: FECHA CONSIGNACION | F14: FECHA PAGO SEGÚN CALENDARIO TRIBUTARIO | G14: DIAS INCUMPLIDOS
A15: Enero | B15: =CONCATENATE(A15,$C$1) -> Enero9 | F15: =VLOOKUP(B15,'Calendario Tributario'!$D$3:$K$122,4,0) -> 43873 | G15: =IF(E15-F15>0,E15-F15,0) -> 0 | H15: =IF(AND(EOMONTH(DATE($A$13,MONTH("1-"&A15&"-"&$A$13),1),0)>=Generales!$B$4,DATE($A$13,MONTH("1-"&A15&"-"&$A$13),1)<=Generales!$C$4),"","FUERA DE RANGO") -> FUERA DE RANGO
A16: Febrero | B16: =CONCATENATE(A16,$C$1) -> Febrero9 | F16: =VLOOKUP(B16,'Calendario Tributario'!$D$3:$K$122,4,0) -> 43901 | G16: =IF(E16-F16<0,0,E16-F16) -> 0 | H16: =IF(AND(EOMONTH(DATE($A$13,MONTH("1-"&A16&"-"&$A$13),1),0)>=Generales!$B$4,DATE($A$13,MONTH("1-"&A16&"-"&$A$13),1)<=Generales!$C$4),"","FUERA DE RANGO") -> FUERA DE RANGO
A17: Marzo | B17: =CONCATENATE(A17,$C$1) -> Marzo9 | F17: =VLOOKUP(B17,'Calendario Tributario'!$D$3:$K$122,4,0) -> 43936 | G17: =IF(E17-F17<0,0,E17-F17) -> 0 | H17: =IF(AND(EOMONTH(DATE($A$13,MONTH("1-"&A17&"-"&$A$13),1),0)>=Generales!$B$4,DATE($A$13,MONTH("1-"&A17&"-"&$A$13),1)<=Generales!$C$4),"","FUERA DE RANGO") -> FUERA DE RANGO
A18: Abril | B18: =CONCATENATE(A18,$C$1) -> Abril9 | F18: =VLOOKUP(B18,'Calendario Tributario'!$D$3:$K$122,4,0) -> 43964 | G18: =IF(E18-F18<0,0,E18-F18) -> 0 | H18: =IF(AND(EOMONTH(DATE($A$13,MONTH("1-"&A18&"-"&$A$13),1),0)>=Generales!$B$4,DATE($A$13,MONTH("1-"&A18&"-"&$A$13),1)<=Generales!$C$4),"","FUERA DE RANGO") -> FUERA DE RANGO
A19: Mayo | B19: =CONCATENATE(A19,$C$1) -> Mayo9 | F19: =VLOOKUP(B19,'Calendario Tributario'!$D$3:$K$122,4,0) -> 43992 | G19: =IF(E19-F19<0,0,E19-F19) -> 0 | H19: =IF(AND(EOMONTH(DATE($A$13,MONTH("1-"&A19&"-"&$A$13),1),0)>=Generales!$B$4,DATE($A$13,MONTH("1-"&A19&"-"&$A$13),1)<=Generales!$C$4),"","FUERA DE RANGO") -> FUERA DE RANGO
A20: Junio | B20: =CONCATENATE(A20,$C$1) -> Junio9 | F20: =VLOOKUP(B20,'Calendario Tributario'!$D$3:$K$122,4,0) -> 44020 | G20: =IF(E20-F20<0,0,E20-F20) -> 0 | H20: =IF(AND(EOMONTH(DATE($A$13,MONTH("1-"&A20&"-"&$A$13),1),0)>=Generales!$B$4,DATE($A$13,MONTH("1-"&A20&"-"&$A$13),1)<=Generales!$C$4),"","FUERA DE RANGO") -> FUERA DE RANGO
A21: Julio | B21: =CONCATENATE(A21,$C$1) -> Julio9 | F21: =VLOOKUP(B21,'Calendario Tributario'!$D$3:$K$122,4,0) -> 44055 | G21: =IF(E21-F21<0,0,E21-F21) -> 0 | H21: =IF(AND(EOMONTH(DATE($A$13,MONTH("1-"&A21&"-"&$A$13),1),0)>=Generales!$B$4,DATE($A$13,MONTH("1-"&A21&"-"&$A$13),1)<=Generales!$C$4),"","FUERA DE RANGO") -> FUERA DE RANGO
A22: Agosto | B22: =CONCATENATE(A22,$C$1) -> Agosto9 | F22: =VLOOKUP(B22,'Calendario Tributario'!$D$3:$K$122,4,0) -> 44083 | G22: =IF(E22-F22<0,0,E22-F22) -> 0 | H22: =IF(AND(EOMONTH(DATE($A$13,MONTH("1-"&A22&"-"&$A$13),1),0)>=Generales!$B$4,DATE($A$13,MONTH("1-"&A22&"-"&$A$13),1)<=Generales!$C$4),"","FUERA DE RANGO") -> FUERA DE RANGO
A23: Septiembre | B23: =CONCATENATE(A23,$C$1) -> Septiembre9 | F23: =VLOOKUP(B23,'Calendario Tributario'!$D$3:$K$122,4,0) -> 44111 | G23: =IF(E23-F23<0,0,E23-F23) -> 0 | H23: =IF(AND(EOMONTH(DATE($A$13,MONTH("1-"&A23&"-"&$A$13),1),0)>=Generales!$B$4,DATE($A$13,MONTH("1-"&A23&"-"&$A$13),1)<=Generales!$C$4),"","FUERA DE RANGO") -> FUERA DE RANGO
A24: Octubre | B24: =CONCATENATE(A24,$C$1) -> Octubre9 | F24: =VLOOKUP(B24,'Calendario Tributario'!$D$3:$K$122,4,0) -> 44146 | G24: =IF(E24-F24<0,0,E24-F24) -> 0 | H24: =IF(AND(EOMONTH(DATE($A$13,MONTH("1-"&A24&"-"&$A$13),1),0)>=Generales!$B$4,DATE($A$13,MONTH("1-"&A24&"-"&$A$13),1)<=Generales!$C$4),"","FUERA DE RANGO") -> FUERA DE RANGO
A25: Noviembre | B25: =CONCATENATE(A25,$C$1) -> Noviembre9 | F25: =VLOOKUP(B25,'Calendario Tributario'!$D$3:$K$122,4,0) -> 44176 | G25: =IF(E25-F25<0,0,E25-F25) -> 0 | H25: =IF(AND(EOMONTH(DATE($A$13,MONTH("1-"&A25&"-"&$A$13),1),0)>=Generales!$B$4,DATE($A$13,MONTH("1-"&A25&"-"&$A$13),1)<=Generales!$C$4),"","FUERA DE RANGO") -> FUERA DE RANGO
A26: Diciembre | B26: =CONCATENATE(A26,$C$1) -> Diciembre9 | F26: =VLOOKUP(B26,'Calendario Tributario'!$D$3:$K$122,4,0) -> 44210 | G26: =IF(E26-F26<0,0,E26-F26) -> 0 | H26: =IF(AND(EOMONTH(DATE($A$13,MONTH("1-"&A26&"-"&$A$13),1),0)>=Generales!$B$4,DATE($A$13,MONTH("1-"&A26&"-"&$A$13),1)<=Generales!$C$4),"","FUERA DE RANGO") -> FUERA DE RANGO
A28: 2021
A29: MES | C29: BANCO | D29: VALOR | E29: FECHA CONSIGNACION | F29: FECHA PAGO SEGÚN CALENDARIO TRIBUTARIO | G29: DIAS INCUMPLIDOS
A30: Enero | B30: =CONCATENATE(A30,$C$1) -> Enero9 | F30: =VLOOKUP(B30,'Calendario Tributario'!$D$3:$K$122,5,0) -> 44246 | G30: =IF(E30-F30<0,0,E30-F30) -> 0 | H30: =IF(AND(EOMONTH(DATE($A$28,MONTH("1-"&A30&"-"&$A$28),1),0)>=Generales!$B$4,DATE($A$28,MONTH("1-"&A30&"-"&$A$28),1)<=Generales!$C$4),"","FUERA DE RANGO") -> FUERA DE RANGO
A31: Febrero | B31: =CONCATENATE(A31,$C$1) -> Febrero9 | F31: =VLOOKUP(B31,'Calendario Tributario'!$D$3:$K$122,5,0) -> 44274 | G31: =IF(E31-F31<0,0,E31-F31) -> 0 | H31: =IF(AND(EOMONTH(DATE($A$28,MONTH("1-"&A31&"-"&$A$28),1),0)>=Generales!$B$4,DATE($A$28,MONTH("1-"&A31&"-"&$A$28),1)<=Generales!$C$4),"","FUERA DE RANGO") -> FUERA DE RANGO
A32: Marzo | B32: =CONCATENATE(A32,$C$1) -> Marzo9 | F32: =VLOOKUP(B32,'Calendario Tributario'!$D$3:$K$122,5,0) -> 44308 | G32: =IF(E32-F32<0,0,E32-F32) -> 0 | H32: =IF(AND(EOMONTH(DATE($A$28,MONTH("1-"&A32&"-"&$A$28),1),0)>=Generales!$B$4,DATE($A$28,MONTH("1-"&A32&"-"&$A$28),1)<=Generales!$C$4),"","FUERA DE RANGO") -> FUERA DE RANGO
A33: Abril | B33: =CONCATENATE(A33,$C$1) -> Abril9 | F33: =VLOOKUP(B33,'Calendario Tributario'!$D$3:$K$122,5,0) -> 44337 | G33: =IF(E33-F33<0,0,E33-F33) -> 0 | H33: =IF(AND(EOMONTH(DATE($A$28,MONTH("1-"&A33&"-"&$A$28),1),0)>=Generales!$B$4,DATE($A$28,MONTH("1-"&A33&"-"&$A$28),1)<=Generales!$C$4),"","FUERA DE RANGO") -> FUERA DE RANGO
A34: Mayo | B34: =CONCATENATE(A34,$C$1) -> Mayo9 | F34: =VLOOKUP(B34,'Calendario Tributario'!$D$3:$K$122,5,0) -> 44369 | G34: =IF(E34-F34<0,0,E34-F34) -> 0 | H34: =IF(AND(EOMONTH(DATE($A$28,MONTH("1-"&A34&"-"&$A$28),1),0)>=Generales!$B$4,DATE($A$28,MONTH("1-"&A34&"-"&$A$28),1)<=Generales!$C$4),"","FUERA DE RANGO") -> FUERA DE RANGO
A35: Junio | B35: =CONCATENATE(A35,$C$1) -> Junio9 | F35: =VLOOKUP(B35,'Calendario Tributario'!$D$3:$K$122,5,0) -> 44398 | G35: =IF(E35-F35<0,0,E35-F35) -> 0 | H35: =IF(AND(EOMONTH(DATE($A$28,MONTH("1-"&A35&"-"&$A$28),1),0)>=Generales!$B$4,DATE($A$28,MONTH("1-"&A35&"-"&$A$28),1)<=Generales!$C$4),"","FUERA DE RANGO") -> FUERA DE RANGO
A36: Julio | B36: =CONCATENATE(A36,$C$1) -> Julio9 | F36: =VLOOKUP(B36,'Calendario Tributario'!$D$3:$K$122,5,0) -> 44431 | G36: =IF(E36-F36<0,0,E36-F36) -> 0 | H36: =IF(AND(EOMONTH(DATE($A$28,MONTH("1-"&A36&"-"&$A$28),1),0)>=Generales!$B$4,DATE($A$28,MONTH("1-"&A36&"-"&$A$28),1)<=Generales!$C$4),"","FUERA DE RANGO") -> FUERA DE RANGO
A37: Agosto | B37: =CONCATENATE(A37,$C$1) -> Agosto9 | F37: =VLOOKUP(B37,'Calendario Tributario'!$D$3:$K$122,5,0) -> 44459 | G37: =IF(E37-F37<0,0,E37-F37) -> 0 | H37: =IF(AND(EOMONTH(DATE($A$28,MONTH("1-"&A37&"-"&$A$28),1),0)>=Generales!$B$4,DATE($A$28,MONTH("1-"&A37&"-"&$A$28),1)<=Generales!$C$4),"","FUERA DE RANGO") -> FUERA DE RANGO
A38: Septiembre | B38: =CONCATENATE(A38,$C$1) -> Septiembre9 | F38: =VLOOKUP(B38,'Calendario Tributario'!$D$3:$K$122,5,0) -> 44489 | G38: =IF(E38-F38<0,0,E38-F38) -> 0 | H38: =IF(AND(EOMONTH(DATE($A$28,MONTH("1-"&A38&"-"&$A$28),1),0)>=Generales!$B$4,DATE($A$28,MONTH("1-"&A38&"-"&$A$28),1)<=Generales!$C$4),"","FUERA DE RANGO") -> FUERA DE RANGO
A39: Octubre | B39: =CONCATENATE(A39,$C$1) -> Octubre9 | F39: =VLOOKUP(B39,'Calendario Tributario'!$D$3:$K$122,5,0) -> 44522 | G39: =IF(E39-F39<0,0,E39-F39) -> 0 | H39: =IF(AND(EOMONTH(DATE($A$28,MONTH("1-"&A39&"-"&$A$28),1),0)>=Generales!$B$4,DATE($A$28,MONTH("1-"&A39&"-"&$A$28),1)<=Generales!$C$4),"","FUERA DE RANGO") -> FUERA DE RANGO
A40: Noviembre | B40: =CONCATENATE(A40,$C$1) -> Noviembre9 | F40: =VLOOKUP(B40,'Calendario Tributario'!$D$3:$K$122,5,0) -> 44552 | G40: =IF(E40-F40<0,0,E40-F40) -> 0 | H40: =IF(AND(EOMONTH(DATE($A$28,MONTH("1-"&A40&"-"&$A$28),1),0)>=Generales!$B$4,DATE($A$28,MONTH("1-"&A40&"-"&$A$28),1)<=Generales!$C$4),"","FUERA DE RANGO") -> FUERA DE RANGO
A41: Diciembre | B41: =CONCATENATE(A41,$C$1) -> Diciembre9 | F41: =VLOOKUP(B41,'Calendario Tributario'!$D$3:$K$122,5,0) -> 44585 | G41: =IF(E41-F41<0,0,E41-F41) -> 0 | H41: =IF(AND(EOMONTH(DATE($A$28,MONTH("1-"&A41&"-"&$A$28),1),0)>=Generales!$B$4,DATE($A$28,MONTH("1-"&A41&"-"&$A$28),1)<=Generales!$C$4),"","FUERA DE RANGO") -> FUERA DE RANGO
A43: 2022
A44: MES | C44: BANCO | D44: VALOR | E44: FECHA CONSIGNACION | F44: FECHA PAGO SEGÚN CALENDARIO TRIBUTARIO | G44: DIAS INCUMPLIDOS
A45: Enero | B45: =CONCATENATE(A45,$C$1) -> Enero9 | F45: =VLOOKUP(B45,'Calendario Tributario'!$D$3:$K$122,6,0) -> 44610 | G45: =IF(E45-F45<0,0,E45-F45) -> 0 | H45: =IF(AND(EOMONTH(DATE($A$43,MONTH("1-"&A45&"-"&$A$43),1),0)>=Generales!$B$4,DATE($A$43,MONTH("1-"&A45&"-"&$A$43),1)<=Generales!$C$4),"","FUERA DE RANGO") -> FUERA DE RANGO
...

Sheet APORTE ESPE
A1: BANCO | B1: VALOR | C1: FECHA PAGO | D1: FECHA FACTURA | E1: ESCRITURA Y FECHA | F1: ¿Extemporáneo?
C2: 43617 | D2: 43586 | F2: =IF((NETWORKDAYS(D2,C2))>5,"SÍ "&(NETWORKDAYS(D2,C2))&" días","NO") -> SÍ 23 días | H2: Tope entre Privados | I2: 28798900 | J2: Valor Derechos
F3: =IF((NETWORKDAYS(D3,C3))>5,"SÍ "&(NETWORKDAYS(D3,C3))&" días","NO") -> NO | H3: Tope entre Privado - Exento | I3: 4326500 | J3: Valor del Aporte Especial | K3: =K2-I3 -> -4326500
F4: =IF((NETWORKDAYS(D4,C4))>5,"SÍ "&(NETWORKDAYS(D4,C4))&" días","NO") -> NO
F5: =IF((NETWORKDAYS(D5,C5))>5,"SÍ "&(NETWORKDAYS(D5,C5))&" días","NO") -> NO
F6: =IF((NETWORKDAYS(D6,C6))>5,"SÍ "&(NETWORKDAYS(D6,C6))&" días","NO") -> NO
F7: =IF((NETWORKDAYS(D7,C7))>5,"SÍ "&(NETWORKDAYS(D7,C7))&" días","NO") -> NO
F8: =IF((NETWORKDAYS(D8,C8))>5,"SÍ "&(NETWORKDAYS(D8,C8))&" días","NO") -> NO
F9: =IF((NETWORKDAYS(D9,C9))>5,"SÍ "&(NETWORKDAYS(D9,C9))&" días","NO") -> NO
F10: =IF((NETWORKDAYS(D10,C10))>5,"SÍ "&(NETWORKDAYS(D10,C10))&" días","NO") -> NO
A12: AÑO 2020
A13: BANCO | B13: VALOR | C13: FECHA PAGO | D13: FECHA FACTURA | E13: ESCRITURA Y FECHA | F13: ¿Extemporáneo?
F14: =IF((NETWORKDAYS(D14,C14))>5,"SÍ "&(NETWORKDAYS(D14,C14))&" días","NO") -> NO | H14: Tope entre Privados | I14: 29893300 | J14: Valor del Derechos
F15: =IF((NETWORKDAYS(D15,C15))>5,"SÍ "&(NETWORKDAYS(D15,C15))&" días","NO") -> NO | H15: Tope entre Privado - Exento | I15: 4490900 | J15: Valor del Aporte Especial | K15: =K14-I15 -> -4490900
F16: =IF((NETWORKDAYS(D16,C16))>5,"SÍ "&(NETWORKDAYS(D16,C16))&" días","NO") -> NO
F17: =IF((NETWORKDAYS(D17,C17))>5,"SÍ "&(NETWORKDAYS(D17,C17))&" días","NO") -> NO
F18: =IF((NETWORKDAYS(D18,C18))>5,"SÍ "&(NETWORKDAYS(D18,C18))&" días","NO") -> NO
F19: =IF((NETWORKDAYS(D19,C19))>5,"SÍ "&(NETWORKDAYS(D19,C19))&" días","NO") -> NO
F20: =IF((NETWORKDAYS(D20,C20))>5,"SÍ "&(NETWORKDAYS(D20,C20))&" días","NO") -> NO
F21: =IF((NETWORKDAYS(D21,C21))>5,"SÍ "&(NETWORKDAYS(D21,C21))&" días","NO") -> NO
A23: AÑO 2021
A24: BANCO | B24: VALOR | C24: FECHA PAGO | D24: FECHA FACTURA | E24: ESCRITURA Y FECHA | F24: ¿Extemporáneo? | G24: Método | H24: Tope entre Privados | I24: 30374600 | J24: Valor Derechos
F25: =IF((NETWORKDAYS(D25,C25))>5,"SÍ "&(NETWORKDAYS(D25,C25))&" días","NO") -> NO | G25: Se verifica tipo de aporte especial generado (entre privados o privado - exento), se verifica el cálculo del aporte y se verifica la cuantía del acto. | H25: Tope entre Privado - Exento | I25: 4563200 | J25: Valor del Aporte Especial | K25: =K24-I24 -> -30374600
F26: =IF((NETWORKDAYS(D26,C26))>5,"SÍ "&(NETWORKDAYS(D26,C26))&" días","NO") -> NO | G26: *Ingresó el dinero en cartera el 6 de mayo de 2021
F27: =IF((NETWORKDAYS(D27,C27))>5,"SÍ "&(NETWORKDAYS(D27,C27))&" días","NO") -> NO
F28: =IF((NETWORKDAYS(D28,C28))>5,"SÍ "&(NETWORKDAYS(D28,C28))&" días","NO") -> NO
F29: =IF((NETWORKDAYS(D29,C29))>5,"SÍ "&(NETWORKDAYS(D29,C29))&" días","NO") -> NO
F30: =IF((NETWORKDAYS(D30,C30))>5,"SÍ "&(NETWORKDAYS(D30,C30))&" días","NO") -> NO
F31: =IF((NETWORKDAYS(D31,C31))>5,"SÍ "&(NETWORKDAYS(D31,C31))&" días","NO") -> NO
F32: =IF((NETWORKDAYS(D32,C32))>5,"SÍ "&(NETWORKDAYS(D32,C32))&" días","NO") -> NO
A35: AÑO 2022
A36: BANCO | B36: VALOR | C36: FECHA PAGO | D36: FECHA FACTURA | E36: ESCRITURA Y FECHA | F36: ¿Extemporáneo? | H36: Tope entre Privados | I36: 32081700 | J36: Valor Derechos
F37: =IF((NETWORKDAYS(D37,C37))>5,"SÍ "&(NETWORKDAYS(D37,C37))&" días","NO") -> NO | H37: Tope entre Privado - Exento | I37: 4819700 | J37: Valor del Aporte Especial | K37: =K36-I36 -> -32081700
F38: =IF((NETWORKDAYS(D38,C38))>5,"SÍ "&(NETWORKDAYS(D38,C38))&" días","NO") -> NO
F39: =IF((NETWORKDAYS(D39,C39))>5,"SÍ "&(NETWORKDAYS(D39,C39))&" días","NO") -> NO
F40: =IF((NETWORKDAYS(D40,C40))>5,"SÍ "&(NETWORKDAYS(D40,C40))&" días","NO") -> NO
F41: =IF((NETWORKDAYS(D41,C41))>5,"SÍ "&(NETWORKDAYS(D41,C41))&" días","NO") -> NO
F42: =IF((NETWORKDAYS(D42,C42))>5,"SÍ "&(NETWORKDAYS(D42,C42))&" días","NO") -> NO
